Workbook

Sheet TDB
C2: 46174
B3: Nbr des demandes ouvertes sur le mois | C3: =COUNTA('tickets ouverts'!A:A)-1 -> 277
B4: Nbr des demandes ouvertes et traitées sur le mois | C4: 228
B5: Nbr des demandes globales Traitées sur le mois | C5: =COUNTA('tickets fermés'!A:A)-1 -> 308
B6: Délai moyen de traitement des tickets ( min ) | C6: =AVERAGE('tickets fermés'!R:R) -> 3.0297687
C19: 46174
B20: Megrine | C20: =COUNTIF('tickets ouverts'!F:F,"Tunisie/Megrine") -> 152
B21: Kram | C21: =COUNTIF('tickets ouverts'!F:F,"Tunisie/Kram") -> 81
B22: Sousse | C22: =COUNTIF('tickets ouverts'!F:F,"Tunisie/Sousse") -> 44
C24: 46174
B25: Megrine / AVS | C25: =COUNTIFS('tickets ouverts'!F:F,"Tunisie/Megrine", 'tickets ouverts'!E:E,"avs") -> 32
B26: Megrine / BBS | C26: =COUNTIFS('tickets ouverts'!F:F,"Tunisie/Megrine", 'tickets ouverts'!E:E,"bbs") -> 19
B27: Megrine / E&T | C27: =COUNTIFS('tickets ouverts'!F:F,"Tunisie/Megrine", 'tickets ouverts'!E:E,"e&t") -> 0
B28: Megrine / supports | C28: =COUNTIFS('tickets ouverts'!F:F,"Tunisie/Megrine", 'tickets ouverts'!E:E,"supports") -> 101
B29: kram / E&T | C29: =COUNTIFS('tickets ouverts'!F:F,"Tunisie/Kram", 'tickets ouverts'!E:E,"E&T") -> 67
B30: kram / supports | C30: =COUNTIFS('tickets ouverts'!F:F,"Tunisie/Kram", 'tickets ouverts'!E:E,"supports") -> 13
B31: kram / BBS | C31: =COUNTIFS('tickets ouverts'!F:F,"Tunisie/Kram", 'tickets ouverts'!E:E,"BBS") -> 1
B32: Sousse / E&T | C32: =COUNTIFS('tickets ouverts'!F:F,"Tunisie/Sousse", 'tickets ouverts'!E:E,"E&T") -> 33
B33: Sousse / supports | C33: =COUNTIFS('tickets ouverts'!F:F,"Tunisie/Sousse", 'tickets ouverts'!E:E,"supports") -> 11
B47: types des demandes ouvertes dans le mois
B48: {=_xlfn.UNIQUE('tickets ouverts'!I2:I278)} -> Souris | C48: =COUNTIF('tickets ouverts'!$I:$I,B48) -> 11
B49: Ligne ADSL / Fibre / Câble | C49: =COUNTIF('tickets ouverts'!$I:$I,B49) -> 1
B50: PC Laptop | C50: =COUNTIF('tickets ouverts'!$I:$I,B50) -> 12
B51: PC accessoires | C51: =COUNTIF('tickets ouverts'!$I:$I,B51) -> 31
B52: Infrastructure Cloud | C52: =COUNTIF('tickets ouverts'!$I:$I,B52) -> 3
B53: Gestion des flux | C53: =COUNTIF('tickets ouverts'!$I:$I,B53) -> 40
B54: ASKit MAJ CMDB | C54: =COUNTIF('tickets ouverts'!$I:$I,B54) -> 23
B55: Hub USB | C55: =COUNTIF('tickets ouverts'!$I:$I,B55) -> 5
B56: Demande d'entrée DNS | C56: =COUNTIF('tickets ouverts'!$I:$I,B56) -> 3
B57: Demande de certificat / Keytab | C57: =COUNTIF('tickets ouverts'!$I:$I,B57) -> 11
B58: Droits administrateur local | C58: =COUNTIF('tickets ouverts'!$I:$I,B58) -> 1
B59: Masterisation d'un poste | C59: =COUNTIF('tickets ouverts'!$I:$I,B59) -> 9
B60: PC Desktop | C60: =COUNTIF('tickets ouverts'!$I:$I,B60) -> 6
... B87: Aftersales | C87: =COUNTIF('tickets ouverts'!$I:$I,B87) -> 3
C91: très insatisfait | D91: Plutôt insatisfait | E91: insatisfait | F91: Satisfait | G91: très satisfait
B92: Satisfaction de traitement | C92: =COUNTIF('Askit -SST KRM enquête'!G:G,1) -> 0 | D92: =COUNTIF('Askit -SST KRM enquête'!G:G,2) -> 0 | E92: =COUNTIF('Askit -SST KRM enquête'!G:G,3) -> 0 | F92: =COUNTIF('Askit -SST KRM enquête'!G:G,4) -> 9 | G92: =COUNTIF('Askit -SST KRM enquête'!G:G,5) -> 37
B93: Communication des opérateurs | C93: =COUNTIF('Askit -SST KRM enquête'!H:H,1) -> 0 | D93: =COUNTIF('Askit -SST KRM enquête'!H:H,2) -> 0 | E93: =COUNTIF('Askit -SST KRM enquête'!H:H,3) -> 0 | F93: =COUNTIF('Askit -SST KRM enquête'!H:H,4) -> 8 | G93: =COUNTIF('Askit -SST KRM enquête'!H:H,5) -> 38
B94: Satisfaction du temps de traitement | C94: =COUNTIF('Askit -SST KRM enquête'!I:I,1) -> 0 | D94: =COUNTIF('Askit -SST KRM enquête'!I:I,2) -> 1 | E94: =COUNTIF('Askit -SST KRM enquête'!I:I,3) -> 0 | F94: =COUNTIF('Askit -SST KRM enquête'!I:I,4) -> 8 | G94: =COUNTIF('Askit -SST KRM enquête'!I:I,5) -> 37
B95: taux de satisfaction | C95: =SUM(C92:C94)/SUM($C$92:$G$94) -> 0 | D95: =SUM(D92:D94)/SUM($C$92:$G$94) -> 0.0072463768 | E95: =SUM(E92:E94)/SUM($C$92:$G$94) -> 0 | F95: =SUM(F92:F94)/SUM($C$92:$G$94) -> 0.18115942 | G95: =SUM(G92:G94)/SUM($C$92:$G$94) -> 0.8115942
B98: Nbr des demandes globales Traitées sur le mois | C98: =C5 -> 308
...

Sheet tickets ouverts
A1: N° ticket | B1: Bénéficiaire | C1: Bénéficiaire ID | D1: Directeur | E1: département | F1: Bénéficiaire : Localisation | G1: Enregistré le | H1: Date de résolution | I1: Sujet | J1: Priorité | K1: E_REPONSES | L1: Description | M1: Bénéficiaire : Niveau de VIP | N1: GROUP_$lng | O1: Groupe courant | P1: Résolu par (groupe) | Q1: Résolu par (intervenant) | R1: GROUP_$lng | S1: Meta Statut | T1: Délai de résolution (min) | U1: Statut ticket | V1: Workflow
A2: S260601_030 | B2: TOUMI, Sonia | C2: G361469 | D2: MASMOUDI, Oussema | E2: BBS | F2: Tunisie/Megrine | G2: 46174.381 | H2: 46185.443 | I2: Souris | J2: 3 | K2: 1 x Souris : 0 EUR1 x Souris filaire : 9.43 EURCentre de coût : S250200 | L2: bonjoursouris est disponiblecordialement | N2: G_IT_DESKTOP_KRM | P2: G_IT_DESKTOP_SST | Q2: BOUFAHJA, Kamel | R2: G_IT_DESKTOP_KRM | S2: Terminé | T2: 4 | U2: Clôturé | V2: WF_REQ_GENERIC_V6.1
A3: S260601_083 | B3: MHAMDI, Amira | C3: G361265 | D3: MAROUFI, Walid | E3: E&T | F3: Tunisie/Kram | G3: 46174.436 | H3: 46188.688 | I3: Souris | J3: 2 | K3: 1 x Souris : 0 EUR1 x Souris sans fil : 12.65 EURCentre de coût : S250300 | L3: BonjourVotre demande est disponibleCdtSANA | N3: G_IT_DESKTOP_KRM | P3: G_IT_DESKTOP_KRM | Q3: GARRAWI, Sana | R3: G_IT_DESKTOP_KRM | S3: Terminé | T3: 4.5222222 | U3: Clôturé | V3: WF_REQ_GENERIC_V6.1
A4: S260601_089 | B4: BEN ALI, Samia | C4: G573274 | D4: MAROUFI, Walid | E4: E&T | F4: Tunisie/Kram | G4: 46174.444 | I4: Ligne ADSL / Fibre / Câble | J4: 3 | K4: 1 x Ligne ADSL / Fibre / Câble : 0 EUREmplacement technique de la ligne (Bât, Etg, Bureau...) : 1 étage site KramLigne : CâbleFournisseur : FreeDésignation commerciale de l'abonnement : !!!!!!Motif du besoin : connexion ethernetCoût mensuel de l'abonnement (euros) : 0Frais de mise en service (euros) : 0Affectation comptable (ordre ou section budgétaire) : 0Responsable de la ligne (+ matricule) : g573274 | N4: G_IT_NETWORK_ADSL | O4: G_IT_NETWORK_KRM | R4: G_IT_NETWORK_ADSL | S4: En cours de traitement | T4: 0 | U4: Redirigé | V4: WF_REQ_GENERIC_V6.1
A5: S260601_090 | B5: ZBIDI, Borhen | C5: G800777 | D5: MAROUFI, Walid | E5: E&T | F5: Tunisie/Sousse | G5: 46174.444 | H5: 46175.372 | I5: PC Laptop | J5: 2 | K5: 1 x PC Laptop : 0 EUR1 x Laptop reconditionné : EUR1 x Aucun écran : USD1 x Aucun sac : EURType : TestConfiguration : Configuration validationOS : WindowsClavier : AZERTYCentre de coût : S250300Email de validation de son DIR pôle à joindre : 2026-06-01_11-00-52.pdf | L5: ​Bonjour,​a { text-decoration: none; color: #464feb; }tr th, tr td { border: 1px solid #e6e6e6; }tr th { background-color: #f5f5f5; }a { text-decoration: none; color: #464feb; }tr th, tr td { border: 1px solid #e6e6e6; }tr th { background-color: #f5f5f5; }Suite à l’urgence et au fait que je ne dispose pas d’un laptop sur site.je vous ai préparé un desktop de test après réception de votre confirmation.Vous pouvez passer au bureau IT pour le récupérer.Cordialement. | N5: G_IT_DESKTOP_SST | P5: G_IT_DESKTOP_QSO | Q5: MFARREJ, Yosri | R5: G_IT_DESKTOP_SST | S5: Terminé | T5: 0.36597222 | U5: Clôturé | V5: WF_REQ_GENERIC_V6.1
A6: S260601_102 | B6: BOUHAJJA, Wiem | C6: G360699 | D6: SAMANDI, Sami | E6: AVS | F6: Tunisie/Megrine | G6: 46174.461 | H6: 46185.365 | I6: PC accessoires | J6: 2 | K6: 1 x PC accessoires : 0 EURN° étiquette du PC (ou modèle) : .Autres accessoires : OuiAutre (préciser l'équipement et la taille) : casqueCentre de coût : S250201 | L6: @équipe IT : si le stock est épuisé , merci de transmettre la référence de cable de sécurité ( ref : Twin Clicksafe Master keyed Lock for All ) à BEN MANSOUR Hakim afin qu'il puisse lancer une demande d'achat bonjourcasque est dispocordialement | N6: G_IT_DESKTOP_SST | P6: G_IT_DESKTOP_SST | Q6: BOUFAHJA, Kamel | R6: G_IT_DESKTOP_SST | S6: Terminé | T6: 3.8416667 | U6: Clôturé | V6: WF_REQ_GENERIC_V6.1
A7: S260601_103 | B7: THELJAOUI, Mohamed | C7: G361247 | D7: BEN ABDALLAH, Mehdi | E7: supports | F7: Tunisie/Megrine | G7: 46174.462 | H7: 46185.326 | I7: Infrastructure Cloud | J7: 3 | K7: 1 x Infrastructure Cloud : 0 EURTitre : Configuration SAML pour supEVALEntité/service : ITEnvironnement : Development/Integration/TestType d'accès : Sagemcom interneCommunication avec réseau Sagemcom : OuiType de service : VM Linux | L7: dejà traité | N7: G_IT_INFRA_BLB | P7: G_IT_INFRA_BLB | Q7: BOUHADANA, David | R7: G_IT_INFRA_BLB | S7: Terminé | T7: 3.8097222 | U7: Clôturé | V7: WF_REQ_GENERIC_V6.1
A8: S260601_105 | B8: GHARDALLOU, Mohamed | C8: G800389 | D8: MAROUFI, Walid | E8: E&T | F8: Tunisie/Sousse | G8: 46174.462 | H8: 46181.397 | I8: Gestion des flux | J8: 2 | K8: 1 x Gestion des flux : 0 EURTitre : gta non accessibleAction demandée : CréationProjet/Application : GTASite destination : EZR (Tunisie/Ezzahra)Adresses IP sources : g800389Adresses IP destination : https://gta.sst.scom:8443/webquartz/ux/loginPort destination : 8443 | L8: Accepter Pour accepter la demande, cliquez simplement sur le bouton d'envoi de ce mail. Ne modifiez pas le texte ci dessous @OPERATION@='SOLVE' @RFC_NUMBER@='S260601_105' @CHOICE@='1' Mohamed Ghardallou Référent Technique Senior E&T (SST) Adresse postale: Parc technologique Innovation City, Sousse 4061 Mobile: +216 99 163 122 | N8: G_IT_NETWORK_BLB | P8: G_IT_SECURITY | Q8: OGRYZEK, Damien | R8: G_IT_NETWORK_BLB | S8: Terminé | T8: 2.1229167 | U8: Clôturé | V8: WF_REQ_GENERIC_V6.1
A9: S260601_120 | B9: JAWEDI, Mohamed Mounawer | C9: G573282 | D9: JANNOT, Christian | E9: supports | F9: Tunisie/Megrine | G9: 46174.48 | H9: 46182.699 | I9: Souris | J9: 3 | K9: 1 x Souris : 0 EUR1 x Souris filaire : 9.43 EURCentre de coût : S250206 | L9: Accepter Pour accepter la demande, cliquez simplement sur le bouton d'envoi de ce mail. Ne modifiez pas le texte ci dessous @OPERATION@='SOLVE' @RFC_NUMBER@='S260601_120' @CHOICE@='1' Bonjoursouris est disponiblecordialement | N9: G_IT_DESKTOP_SST | P9: G_IT_DESKTOP_SST | Q9: BOUFAHJA, Kamel | R9: G_IT_DESKTOP_SST | S9: Terminé | T9: 2.8444444 | U9: Clôturé | V9: WF_REQ_GENERIC_V6.1
A10: S260601_180 | B10: HAMMOUDA, Imen | C10: G361243 | D10: BEN ABDALLAH, Mehdi | E10: supports | F10: Tunisie/Megrine | G10: 46174.592 | H10: 46174.846 | I10: ASKit MAJ CMDB | J10: 3 | K10: Nom du serveur : BLB28063Système d'exploitation du serveur : Debian 13Type de serveur : Virtuel (VM)Espace disque du serveur (en Go) : 60 GO sous /home + 160 GO sous /varRAM Serveur (en Go) : 8Nombre de processeur et modèle pour serveur : 4Expression du besoin : Bonjour, Pouvez-vous créer cette machine dans le VLAN: DMZ_Privee VLAN 922. la machine va remplacer RMM08150, elle doit être dans le même VLAN. Cordialement, Imen Besoin en supervision : OuiBesoin en sauvegarde : OuiDescription de ce qui doit être sauvegardé : sauvegarde machineNature du serveur : PRODContact technique : HAMMOUDA, Imen - G361243Besoin réseau : Accès uniquement par SagemcomDate de mise en œuvre souhaitée : 15/06/2026Besoin d'une seconde sauvegarde sur un site distinct de Bois-Colombes : NonMatrice de flux : 95156Titre : VM MIGRATION COORD GAZPAR PRODResponsable applicatif : TALMOUDI, Abdelkader - G603655Contact mainteneur : MKADDEM, Oussama - G701089Besoin certificat HTTPS : NonBesoin d'un alias DNS (à créer ou modifier) : NonNetmask : 255.255.255.248VLAN : 3257Gateway : 10.81.130.185IP serveur : 10.81.130.187Action : CréationHébergement du serveur : Central (BLB)Nouveau VLAN : NonService/CI associé au serveur : COORDINATEUR_1G_GAZPARBesoin d'envoyer des mails via nos passerelles SMTP : OuiModèle : VMware Virtual PlatformDescription serveur : Coordinateur PROD 1G GAZPARCréation du serveur : OuiCréation serveur en CI : OuiLien CI service-serveur : OuiNom du serveur : BLB28063Système d'exploitation du serveur : Debian 13Type de serveur : Virtuel (VM)Espace disque du serveur (en Go) : 60 GO sous /home + 160 GO sous /varRAM Serveur (en Go) : 8Nombre de processeur et modèle pour serveur : 4Expression du besoin : Bonjour, Pouvez-vous créer cette machine dans le VLAN: DMZ_Privee VLAN 922. la machine va remplacer RMM08150, elle doit être dans le même VLAN. Cordialement, Imen Besoin en supervision : OuiBesoin en sauvegarde : OuiDescription de ce qui doit être sauvegardé : sauvegarde machineNature du serveur : PRODContact technique : HAMMOUDA, Imen - G361243Besoin réseau : Accès uniquement par SagemcomDate de mise en œuvre souhaitée : 15/06/2026Besoin d'une seconde sauvegarde sur un site distinct de Bois-Colombes : NonMatrice de flux : 95156Titre : VM MIGRATION COORD GAZPAR PRODResponsable applicatif : TALMOUDI, Abdelkader - G603655Contact mainteneur : MKADDEM, Oussama - G701089Besoin certificat HTTPS : NonBesoin d'un alias DNS (à créer ou modifier) : NonNetmask : 255.255.255.248VLAN : 3257Gateway : 10.81.130.185IP serveur : 10.81.130.187Action : CréationHébergement du serveur : Central (BLB)Nouveau VLAN : NonService/CI associé au serveur : COORDINATEUR_1G_GAZPARBesoin d'envoyer des mails via nos passerelles SMTP : OuiModèle : VMware Virtual PlatformDescription serveur : Coordinateur PROD 1G GAZPAR | N10: G_IT_SC_ASKIT | O10: G_IT_SC_ASKIT | P10: G_IT_SC_ASKIT | Q10: ABBAR, Ahcene | R10: G_IT_SC_ASKIT | S10: Terminé | T10: 0 | U10: Clôturé | V10: WF_CMDB_SERV_ASKIT
A11: S260601_184 | B11: CHAABANI, Sirine | C11: G800208 | D11: MAROUFI, Walid | E11: E&T | F11: Tunisie/Kram | G11: 46174.601 | H11: 46175.446 | I11: Hub USB | J11: 2 | K11: 1 x Hub USB : 18 EURNombre de ports : 7Centre de coût : S250300 | L11: Bonjour,Nous procédons à la clôture de votre ticket. Nous confirmons que les hubs USB ne sont pas fournis par notre service, veuillez contacter Karim MCHITAMerci de votre compréhension.Cdt, | N11: G_IT_DESKTOP_KRM | P11: G_IT_DESKTOP_KRM | Q11: DRIDI, Rimeh | R11: G_IT_DESKTOP_KRM | S11: Terminé | T11: 0.28263889 | U11: Clôturé | V11: WF_REQ_GENERIC_V6.1
A12: S260601_197 | B12: OMRANI, Ibrahim | C12: G800291 | D12: MAROUFI, Walid | E12: E&T | F12: Tunisie/Kram | G12: 46174.617 | H12: 46175.445 | I12: Hub USB | J12: 2 | K12: 1 x Hub USB : 18 EURNombre de ports : 4 Centre de coût : S250300 | L12: Bonjour,Nous procédons à la clôture de votre ticket. Nous confirmons que les hubs USB ne sont pas fournis par notre service, veuillez contacter Karim MCHITAMerci de votre compréhension.Cdt, | N12: G_IT_DESKTOP_KRM | P12: G_IT_DESKTOP_KRM | Q12: DRIDI, Rimeh | R12: G_IT_DESKTOP_KRM | S12: Terminé | T12: 0.26666667 | U12: Clôturé | V12: WF_REQ_GENERIC_V6.1
A13: S260601_219 | B13: DALAOUS, Wael | C13: G800394 | D13: BEN ABDALLAH, Mehdi | E13: supports | F13: Tunisie/Megrine | G13: 46174.634 | H13: 46176.5 | I13: Demande d'entrée DNS | J13: 3 | K13: 1 x Demande d'entrée DNS : 0 EURAction : CréationType de DNS : Alias (CNAME)Nom DNS souhaité : argocd-avs.blb.scomNom technique de la machine cible : 10.80.185.37 | N13: G_IT_INFRA_BLB | P13: G_IT_INFRA_BLB | Q13: GAUTREAU, Fabien | R13: G_IT_INFRA_BLB | S13: Terminé | T13: 0.74166667 | U13: Clôturé | V13: WF_REQ_GENERIC_V6.1
A14: S260601_221 | B14: DALAOUS, Wael | C14: G800394 | D14: BEN ABDALLAH, Mehdi | E14: supports | F14: Tunisie/Megrine | G14: 46174.636 | H14: 46176.497 | I14: Demande de certificat / Keytab | J14: 3 | K14: 1 x Demande de certificat / Keytab : 0 EURType de demande : CertificatNom DNS souhaité : argocd-avs.blb.scom | N14: G_IT_INFRA_BLB | P14: G_IT_INFRA_BLB | Q14: GAUTREAU, Fabien | R14: G_IT_INFRA_BLB | S14: Terminé | T14: 0.73611111 | U14: Clôturé | V14: WF_REQ_GENERIC_V6.1
A15: S260601_227 | B15: JAAFAR, Fatma | C15: G361305 | D15: MAROUFI, Walid | E15: E&T | F15: Tunisie/Kram | G15: 46174.644 | H15: 46175.666 | I15: Souris | J15: 2 | K15: 1 x Souris : 0 EUR1 x Souris filaire : 9.43 EURCentre de coût : S250300 | L15: Bonjourdemande traitéeCdtSANA | N15: G_IT_DESKTOP_KRM | P15: G_IT_DESKTOP_KRM | Q15: GARRAWI, Sana | R15: G_IT_DESKTOP_KRM | S15: Terminé | T15: 0.45972222 | U15: Clôturé | V15: WF_REQ_GENERIC_V6.1
A16: S260601_241 | B16: GOUTALI, Ghada | C16: G701944 | D16: SAMANDI, Sami | E16: AVS | F16: Tunisie/Megrine | G16: 46174.654 | H16: 46184.401 | I16: Souris | J16: 3 | K16: 1 x Souris : 0 EUR1 x Souris filaire : 9.43 EURCentre de coût : S250201 | L16: bonjoursouris est disponiblecordialement | N16: G_IT_DESKTOP_SST | P16: G_IT_DESKTOP_SST | Q16: BOUFAHJA, Kamel | R16: G_IT_DESKTOP_SST | S16: Terminé | T16: 3.2479167 | U16: Clôturé | V16: WF_REQ_GENERIC_V6.1
A17: S260601_242 | B17: JAOUADI, Wassim | C17: G701244 | D17: BEN SALAH, Naoufel | E17: BBS | F17: Tunisie/Megrine | G17: 46174.655 | I17: Droits administrateur local | J17: 2 | K17: 1 x Droits administrateur local : 0 EURQuel est le n° de l'étiquette du PC (code barre) ? : P1311003Nom et matricule de l'ancien propriétaire : Ameni SammariCette machine devient-elle la votre ? : OuiType OS : Linux | N17: G_IT_DESKTOP_SST | O17: G_IT_DESKTOP_SST | R17: G_IT_DESKTOP_SST | S17: En cours de traitement | T17: 0 | U17: En cours | V17: WF_REQ_GENERIC_V6.1
A18: S260601_255 | B18: MBRAEK, Bochra | C18: G800299 | D18: BEN SALAH, Naoufel | E18: BBS | F18: Tunisie/Megrine | G18: 46174.673 | H18: 46202.45 | I18: Masterisation d'un poste | J18: 2 | K18: 1 x Masterisation d'un poste : 0 EURChoix de l'OS : LinuxDoit-on sauvegarder les données ? : NonNom de l'ancien propriétaire : Mehrez RekikN° de code barre du PC concerné par la masterisation : p1312898Trigramme site (pour hostname PC) : localhost.localdomain | L18: Bonjour,Desktop est disponibleCordialement | N18: G_IT_DESKTOP_SST | P18: G_IT_DESKTOP_SST | Q18: ADOUKA, Mohamed | R18: G_IT_DESKTOP_SST | S18: Terminé | T18: 8.5270833 | U18: Clôturé | V18: WF_REQ_GENERIC_V6.1
A19: S260601_275 | B19: RAHMANI, Ameni | C19: G701934 | D19: MASMOUDI, Oussema | E19: BBS | F19: Tunisie/Megrine | G19: 46174.736 | H19: 46191.455 | I19: Masterisation d'un poste | J19: 2 | K19: 1 x Masterisation d'un poste : 0 EURChoix de l'OS : LinuxDoit-on sauvegarder les données ? : OuiNom de l'ancien propriétaire : Rahmani AmeniN° de code barre du PC concerné par la masterisation : P1311469 | L19: Bonjour,Demande bien traitéCdt. | N19: G_IT_DESKTOP_SST | P19: G_IT_DESKTOP_SST | Q19: ADOUKA, Mohamed | R19: G_IT_DESKTOP_SST | S19: Terminé | T19: 5.4069444 | U19: Clôturé | V19: WF_REQ_GENERIC_V6.1
A20: S260602_013 | B20: HAMMOUDA, Imen | C20: G361243 | D20: BEN ABDALLAH, Mehdi | E20: supports | F20: Tunisie/Megrine | G20: 46175.297 | H20: 46175.45 | I20: ASKit MAJ CMDB | J20: 3 | K20: Système d'exploitation du serveur : Debian 13Type de serveur : Virtuel (VM)Nom du serveur : BLB28058Espace disque du serveur (en Go) : 20 GO sous /home + 60 GO sous /varBesoin en supervision : OuiRAM Serveur (en Go) : 8Nombre de processeur et modèle pour serveur : 4Expression du besoin : Bonjour, Pouvez-vous créer cette machine dans le VLAN: DMZ_Privee VLAN 922. la machine va remplacer RMM08213, elle doit être dans le même VLAN. Cordialement, Imen Description de ce qui doit être sauvegardé : Sauvegarde machineBesoin en sauvegarde : OuiNature du serveur : PRODContact technique : HAMMOUDA, Imen - G361243Besoin réseau : Accès uniquement par SagemcomDate de mise en œuvre souhaitée : 25/07/2026Matrice de flux : 95211Titre : VM MIGRATION SAV LINKY PRODBesoin d'une seconde sauvegarde sur un site distinct de Bois-Colombes : NonContact mainteneur : MKADDEM, Oussama - G701089Responsable applicatif : TALMOUDI, Abdelkader - G603655Besoin certificat HTTPS : NonNetmask : 255.255.255.248Besoin d'un alias DNS (à créer ou modifier) : NonVLAN : 3258Gateway : 10.81.130.193IP serveur : 10.81.130.197Hébergement du serveur : Central (BLB)Action : CréationNouveau VLAN : NonService/CI associé au serveur : CORP_PORTAL_SAVBesoin d'envoyer des mails via nos passerelles SMTP : OuiModèle : VMware Virtual PlatformDescription serveur : SAV LINKY PROD 1GCréation du serveur : OuiCréation serveur en CI : OuiLien CI service-serveur : OuiSystème d'exploitation du serveur : Debian 13Type de serveur : Virtuel (VM)Nom du serveur : BLB28058Espace disque du serveur (en Go) : 20 GO sous /home + 60 GO sous /varBesoin en supervision : OuiRAM Serveur (en Go) : 8Nombre de processeur et modèle pour serveur : 4Expression du besoin : Bonjour, Pouvez-vous créer cette machine dans le VLAN: DMZ_Privee VLAN 922. la machine va remplacer RMM08213, elle doit être dans le même VLAN. Cordialement, Imen Description de ce qui doit être sauvegardé : Sauvegarde machineBesoin en sauvegarde : OuiNature du serveur : PRODContact technique : HAMMOUDA, Imen - G361243Besoin réseau : Accès uniquement par SagemcomDate de mise en œuvre souhaitée : 25/07/2026Matrice de flux : 95211Titre : VM MIGRATION SAV LINKY PRODBesoin d'une seconde sauvegarde sur un site distinct de Bois-Colombes : NonContact mainteneur : MKADDEM, Oussama - G701089Responsable applicatif : TALMOUDI, Abdelkader - G603655Besoin certificat HTTPS : NonNetmask : 255.255.255.248Besoin d'un alias DNS (à créer ou modifier) : NonVLAN : 3258Gateway : 10.81.130.193IP serveur : 10.81.130.197Hébergement du serveur : Central (BLB)Action : CréationNouveau VLAN : NonService/CI associé au serveur : CORP_PORTAL_SAVBesoin d'envoyer des mails via nos passerelles SMTP : OuiModèle : VMware Virtual PlatformDescription serveur : SAV LINKY PROD 1G | N20: G_IT_SC_ASKIT | O20: G_IT_SC_ASKIT | P20: G_IT_SC_ASKIT | Q20: ABBAR, Ahcene | R20: G_IT_SC_ASKIT | S20: Terminé | T20: 0 | U20: Clôturé | V20: WF_CMDB_SERV_ASKIT
A21: S260602_014 | B21: HAMMOUDA, Imen | C21: G361243 | D21: BEN ABDALLAH, Mehdi | E21: supports | F21: Tunisie/Megrine | G21: 46175.298 | H21: 46175.45 | I21: ASKit MAJ CMDB | J21: 3 | K21: Nom du serveur : BLB28061Type de serveur : Virtuel (VM)Système d'exploitation du serveur : Debian 13Espace disque du serveur (en Go) : 20 GO sous /home + 30 GO sous /varRAM Serveur (en Go) : 4Nombre de processeur et modèle pour serveur : 4Expression du besoin : Bonjour, Pouvez-vous créer cette machine dans le VLAN: DMZ_Privee VLAN 922. la machine va remplacer RMM08451, elle doit être dans le même VLAN. Cordialement, Imen Besoin en supervision : OuiBesoin en sauvegarde : OuiDescription de ce qui doit être sauvegardé : sauvegarde machineNature du serveur : PRODContact technique : HAMMOUDA, Imen - G361243Besoin réseau : Accès uniquement par SagemcomDate de mise en œuvre souhaitée : 30/08/2026Besoin d'une seconde sauvegarde sur un site distinct de Bois-Colombes : NonMatrice de flux : 95163Titre : VM MIGRATION COORD ENSO PRODResponsable applicatif : TALMOUDI, Abdelkader - G603655Contact mainteneur : MKADDEM, Oussama - G701089Besoin certificat HTTPS : NonBesoin d'un alias DNS (à créer ou modifier) : NonNetmask : 255.255.255.248VLAN : 3011Gateway : 10.81.128.89IP serveur : 10.81.128.93Action : CréationHébergement du serveur : Central (BLB)Nouveau VLAN : NonService/CI associé au serveur : COORDINATEUR_ 1G_ENSOBesoin d'envoyer des mails via nos passerelles SMTP : OuiModèle : VMware Virtual PlatformDescription serveur : Coordinateur PROD 1G ENSOCréation du serveur : OuiCréation serveur en CI : OuiLien CI service-serveur : OuiNom du serveur : BLB28061Type de serveur : Virtuel (VM)Système d'exploitation du serveur : Debian 13Espace disque du serveur (en Go) : 20 GO sous /home + 30 GO sous /varRAM Serveur (en Go) : 4Nombre de processeur et modèle pour serveur : 4Expression du besoin : Bonjour, Pouvez-vous créer cette machine dans le VLAN: DMZ_Privee VLAN 922. la machine va remplacer RMM08451, elle doit être dans le même VLAN. Cordialement, Imen Besoin en supervision : OuiBesoin en sauvegarde : OuiDescription de ce qui doit être sauvegardé : sauvegarde machineNature du serveur : PRODContact technique : HAMMOUDA, Imen - G361243Besoin réseau : Accès uniquement par SagemcomDate de mise en œuvre souhaitée : 30/08/2026Besoin d'une seconde sauvegarde sur un site distinct de Bois-Colombes : NonMatrice de flux : 95163Titre : VM MIGRATION COORD ENSO PRODResponsable applicatif : TALMOUDI, Abdelkader - G603655Contact mainteneur : MKADDEM, Oussama - G701089Besoin certificat HTTPS : NonBesoin d'un alias DNS (à créer ou modifier) : NonNetmask : 255.255.255.248VLAN : 3011Gateway : 10.81.128.89IP serveur : 10.81.128.93Action : CréationHébergement du serveur : Central (BLB)Nouveau VLAN : NonService/CI associé au serveur : COORDINATEUR_ 1G_ENSOBesoin d'envoyer des mails via nos passerelles SMTP : OuiModèle : VMware Virtual PlatformDescription serveur : Coordinateur PROD 1G ENSO | N21: G_IT_SC_ASKIT | O21: G_IT_SC_ASKIT | P21: G_IT_SC_ASKIT | Q21: ABBAR, Ahcene | R21: G_IT_SC_ASKIT | S21: Terminé | T21: 0 | U21: Clôturé | V21: WF_CMDB_SERV_ASKIT
A22: S260602_015 | B22: HAMMOUDA, Imen | C22: G361243 | D22: BEN ABDALLAH, Mehdi | E22: supports | F22: Tunisie/Megrine | G22: 46175.299 | H22: 46175.45 | I22: ASKit MAJ CMDB | J22: 3 | K22: Nom du serveur : BLB28059Type de serveur : Virtuel (VM)Système d'exploitation du serveur : Debian 13Espace disque du serveur (en Go) : 20 GO sous /home + 20 GO sous /varRAM Serveur (en Go) : 4Nombre de processeur et modèle pour serveur : 4Expression du besoin : Bonjour, Pouvez-vous créer cette machine dans le VLAN: DMZ_Privee VLAN 922. la machine va remplacer RMM08376, elle doit être dans le même VLAN. Cordialement, Imen Besoin en supervision : OuiBesoin en sauvegarde : OuiDescription de ce qui doit être sauvegardé : Sauvegarde machineNature du serveur : PRODContact technique : HAMMOUDA, Imen - G361243Besoin réseau : Accès uniquement par SagemcomDate de mise en œuvre souhaitée : 26/06/2026Besoin d'une seconde sauvegarde sur un site distinct de Bois-Colombes : NonMatrice de flux : 95206Titre : VM MIGRATION COORD EEHC PRODResponsable applicatif : TALMOUDI, Abdelkader - G603655Contact mainteneur : MKADDEM, Oussama - G701089Besoin certificat HTTPS : NonBesoin d'un alias DNS (à créer ou modifier) : NonNetmask : 255.255.255.248VLAN : 3003Gateway : 10.81.128.25IP serveur : 10.81.128.29Action : CréationHébergement du serveur : Central (BLB)Nouveau VLAN : NonService/CI associé au serveur : COORDINATEUR_2G_EGYPTE_EEHCBesoin d'envoyer des mails via nos passerelles SMTP : OuiModèle : VMware Virtual PlatformDescription serveur : Coordinateur PROD 1G EEHCCréation du serveur : OuiCréation serveur en CI : OuiLien CI service-serveur : OuiNom du serveur : BLB28059Type de serveur : Virtuel (VM)Système d'exploitation du serveur : Debian 13Espace disque du serveur (en Go) : 20 GO sous /home + 20 GO sous /varRAM Serveur (en Go) : 4Nombre de processeur et modèle pour serveur : 4Expression du besoin : Bonjour, Pouvez-vous créer cette machine dans le VLAN: DMZ_Privee VLAN 922. la machine va remplacer RMM08376, elle doit être dans le même VLAN. Cordialement, Imen Besoin en supervision : OuiBesoin en sauvegarde : OuiDescription de ce qui doit être sauvegardé : Sauvegarde machineNature du serveur : PRODContact technique : HAMMOUDA, Imen - G361243Besoin réseau : Accès uniquement par SagemcomDate de mise en œuvre souhaitée : 26/06/2026Besoin d'une seconde sauvegarde sur un site distinct de Bois-Colombes : NonMatrice de flux : 95206Titre : VM MIGRATION COORD EEHC PRODResponsable applicatif : TALMOUDI, Abdelkader - G603655Contact mainteneur : MKADDEM, Oussama - G701089Besoin certificat HTTPS : NonBesoin d'un alias DNS (à créer ou modifier) : NonNetmask : 255.255.255.248VLAN : 3003Gateway : 10.81.128.25IP serveur : 10.81.128.29Action : CréationHébergement du serveur : Central (BLB)Nouveau VLAN : NonService/CI associé au serveur : COORDINATEUR_2G_EGYPTE_EEHCBesoin d'envoyer des mails via nos passerelles SMTP : OuiModèle : VMware Virtual PlatformDescription serveur : Coordinateur PROD 1G EEHC | N22: G_IT_SC_ASKIT | O22: G_IT_SC_ASKIT | P22: G_IT_SC_ASKIT | Q22: ABBAR, Ahcene | R22: G_IT_SC_ASKIT | S22: Terminé | T22: 0 | U22: Clôturé | V22: WF_CMDB_SERV_ASKIT
A23: S260602_016 | B23: HAMMOUDA, Imen | C23: G361243 | D23: BEN ABDALLAH, Mehdi | E23: supports | F23: Tunisie/Megrine | G23: 46175.301 | H23: 46175.45 | I23: ASKit MAJ CMDB | J23: 3 | K23: Nom du serveur : BLB29037Type de serveur : Virtuel (VM)Système d'exploitation du serveur : Debian 13Espace disque du serveur (en Go) : 20 GO sous /home + 20 GO sous /varRAM Serveur (en Go) : 4Nombre de processeur et modèle pour serveur : 4Expression du besoin : Bonjour, Pouvez-vous créer cette machine dans le VLAN: DMZ_Privee VLAN 922. la machine va remplacer RMM08450, elle doit être dans le même VLAN. Cordialement, Imen Besoin en supervision : OuiBesoin en sauvegarde : OuiDescription de ce qui doit être sauvegardé : Sauvegarde machineNature du serveur : VALContact technique : HAMMOUDA, Imen - G361243Besoin réseau : Accès uniquement par SagemcomDate de mise en œuvre souhaitée : 31/07/2026Matrice de flux : 95162Titre : VM MIGRATION COORD ENSO VALResponsable applicatif : TALMOUDI, Abdelkader - G603655Contact mainteneur : MKADDEM, Oussama - G701089Besoin certificat HTTPS : NonBesoin d'un alias DNS (à créer ou modifier) : NonNetmask : 255.255.255.248VLAN : 3011Gateway : 10.81.128.89IP serveur : 10.81.128.92Action : CréationHébergement du serveur : Central (BLB)Nouveau VLAN : NonService/CI associé au serveur : COORDINATEUR_ 1G_ENSOBesoin d'envoyer des mails via nos passerelles SMTP : OuiModèle : VMware Virtual PlatformDescription serveur : Coordinateur VAL 1G ENSOCréation du serveur : OuiCréation serveur en CI : OuiLien CI service-serveur : OuiNom du serveur : BLB29037Type de serveur : Virtuel (VM)Système d'exploitation du serveur : Debian 13Espace disque du serveur (en Go) : 20 GO sous /home + 20 GO sous /varRAM Serveur (en Go) : 4Nombre de processeur et modèle pour serveur : 4Expression du besoin : Bonjour, Pouvez-vous créer cette machine dans le VLAN: DMZ_Privee VLAN 922. la machine va remplacer RMM08450, elle doit être dans le même VLAN. Cordialement, Imen Besoin en supervision : OuiBesoin en sauvegarde : OuiDescription de ce qui doit être sauvegardé : Sauvegarde machineNature du serveur : VALContact technique : HAMMOUDA, Imen - G361243Besoin réseau : Accès uniquement par SagemcomDate de mise en œuvre souhaitée : 31/07/2026Matrice de flux : 95162Titre : VM MIGRATION COORD ENSO VALResponsable applicatif : TALMOUDI, Abdelkader - G603655Contact mainteneur : MKADDEM, Oussama - G701089Besoin certificat HTTPS : NonBesoin d'un alias DNS (à créer ou modifier) : NonNetmask : 255.255.255.248VLAN : 3011Gateway : 10.81.128.89IP serveur : 10.81.128.92Action : CréationHébergement du serveur : Central (BLB)Nouveau VLAN : NonService/CI associé au serveur : COORDINATEUR_ 1G_ENSOBesoin d'envoyer des mails via nos passerelles SMTP : OuiModèle : VMware Virtual PlatformDescription serveur : Coordinateur VAL 1G ENSO | N23: G_IT_SC_ASKIT | O23: G_IT_SC_ASKIT | P23: G_IT_SC_ASKIT | Q23: ABBAR, Ahcene | R23: G_IT_SC_ASKIT | S23: Terminé | T23: 0 | U23: Clôturé | V23: WF_CMDB_SERV_ASKIT
A24: S260602_017 | B24: HAMMOUDA, Imen | C24: G361243 | D24: BEN ABDALLAH, Mehdi | E24: supports | F24: Tunisie/Megrine | G24: 46175.301 | H24: 46175.449 | I24: ASKit MAJ CMDB | J24: 3 | K24: Nom du serveur : BLB29038Type de serveur : Virtuel (VM)Système d'exploitation du serveur : Debian 13Espace disque du serveur (en Go) : 20 GO sous /home + 20 GO sous /varRAM Serveur (en Go) : 4Nombre de processeur et modèle pour serveur : 4Expression du besoin : Bonjour, Pouvez-vous créer cette machine dans le VLAN: DMZ_Privee VLAN 922. la machine va remplacer rmm08417, elle doit être dans le même VLAN. Cordialement, Imen Besoin en supervision : OuiBesoin en sauvegarde : OuiDescription de ce qui doit être sauvegardé : Sauvegarde machineNature du serveur : VALContact technique : HAMMOUDA, Imen - G361243Besoin réseau : Accès uniquement par SagemcomDate de mise en œuvre souhaitée : 01/07/2026Matrice de flux : 95159Titre : VM MIGRATION COORD SMARTVILLAG VALResponsable applicatif : TALMOUDI, Abdelkader - G603655Contact mainteneur : MKADDEM, Oussama - G701089Besoin certificat HTTPS : NonBesoin d'un alias DNS (à créer ou modifier) : NonNetmask : 255.255.255.248VLAN : 3008Gateway : 10.81.128.65IP serveur : 10.81.128.68Action : CréationHébergement du serveur : Central (BLB)Nouveau VLAN : NonService/CI associé au serveur : COORDINATEUR_ 1G_SMART_VILLAGEBesoin d'envoyer des mails via nos passerelles SMTP : OuiModèle : VMware Virtual PlatformDescription serveur : Coordinateur VAL 1G SMARTVILLAGCréation du serveur : OuiCréation serveur en CI : OuiLien CI service-serveur : OuiNom du serveur : BLB29038Type de serveur : Virtuel (VM)Système d'exploitation du serveur : Debian 13Espace disque du serveur (en Go) : 20 GO sous /home + 20 GO sous /varRAM Serveur (en Go) : 4Nombre de processeur et modèle pour serveur : 4Expression du besoin : Bonjour, Pouvez-vous créer cette machine dans le VLAN: DMZ_Privee VLAN 922. la machine va remplacer rmm08417, elle doit être dans le même VLAN. Cordialement, Imen Besoin en supervision : OuiBesoin en sauvegarde : OuiDescription de ce qui doit être sauvegardé : Sauvegarde machineNature du serveur : VALContact technique : HAMMOUDA, Imen - G361243Besoin réseau : Accès uniquement par SagemcomDate de mise en œuvre souhaitée : 01/07/2026Matrice de flux : 95159Titre : VM MIGRATION COORD SMARTVILLAG VALResponsable applicatif : TALMOUDI, Abdelkader - G603655Contact mainteneur : MKADDEM, Oussama - G701089Besoin certificat HTTPS : NonBesoin d'un alias DNS (à créer ou modifier) : NonNetmask : 255.255.255.248VLAN : 3008Gateway : 10.81.128.65IP serveur : 10.81.128.68Action : CréationHébergement du serveur : Central (BLB)Nouveau VLAN : NonService/CI associé au serveur : COORDINATEUR_ 1G_SMART_VILLAGEBesoin d'envoyer des mails via nos passerelles SMTP : OuiModèle : VMware Virtual PlatformDescription serveur : Coordinateur VAL 1G SMARTVILLAG | N24: G_IT_SC_ASKIT | O24: G_IT_SC_ASKIT | P24: G_IT_SC_ASKIT | Q24: ABBAR, Ahcene | R24: G_IT_SC_ASKIT | S24: Terminé | T24: 0 | U24: Clôturé | V24: WF_CMDB_SERV_ASKIT
A25: S260602_018 | B25: HAMMOUDA, Imen | C25: G361243 | D25: BEN ABDALLAH, Mehdi | E25: supports | F25: Tunisie/Megrine | G25: 46175.302 | H25: 46175.449 | I25: ASKit MAJ CMDB | J25: 3 | K25: Nom du serveur : BLB28064Type de serveur : Virtuel (VM)Système d'exploitation du serveur : Debian 13Espace disque du serveur (en Go) : 20 GO sous /home + 60 GO sous /varRAM Serveur (en Go) : 8 GoNombre de processeur et modèle pour serveur : 4Expression du besoin : Bonjour, Pouvez-vous créer cette machine dans le VLAN: DMZ_Privee VLAN 922. la machine va remplacer RMM08409, elle doit être dans le même VLAN. Cordialement, Imen Besoin en supervision : OuiBesoin en sauvegarde : OuiDescription de ce qui doit être sauvegardé : sauvegarde machineNature du serveur : PRODContact technique : HAMMOUDA, Imen - G361243Besoin réseau : Accès uniquement par SagemcomDate de mise en œuvre souhaitée : 22/05/2026Besoin d'une seconde sauvegarde sur un site distinct de Bois-Colombes : NonMatrice de flux : 95153Titre : VM MIGRATION COORD REGAZ PRODResponsable applicatif : TALMOUDI, Abdelkader - G603655Contact mainteneur : MKADDEM, Oussama - G701089Besoin certificat HTTPS : NonBesoin d'un alias DNS (à créer ou modifier) : NonNetmask : 255.255.255.248VLAN : 3006Gateway : 10.81.128.49IP serveur : 10.81.128.54Action : CréationHébergement du serveur : Central (BLB)Nouveau VLAN : NonService/CI associé au serveur : COORDINATEUR_1G_REGAZ_GEGBesoin d'envoyer des mails via nos passerelles SMTP : OuiModèle : VMware Virtual PlatformDescription serveur : Coordinateur PROD 1G REGAZCréation du serveur : OuiCréation serveur en CI : OuiLien CI service-serveur : OuiNom du serveur : BLB28064Type de serveur : Virtuel (VM)Système d'exploitation du serveur : Debian 13Espace disque du serveur (en Go) : 20 GO sous /home + 60 GO sous /varRAM Serveur (en Go) : 8 GoNombre de processeur et modèle pour serveur : 4Expression du besoin : Bonjour, Pouvez-vous créer cette machine dans le VLAN: DMZ_Privee VLAN 922. la machine va remplacer RMM08409, elle doit être dans le même VLAN. Cordialement, Imen Besoin en supervision : OuiBesoin en sauvegarde : OuiDescription de ce qui doit être sauvegardé : sauvegarde machineNature du serveur : PRODContact technique : HAMMOUDA, Imen - G361243Besoin réseau : Accès uniquement par SagemcomDate de mise en œuvre souhaitée : 22/05/2026Besoin d'une seconde sauvegarde sur un site distinct de Bois-Colombes : NonMatrice de flux : 95153Titre : VM MIGRATION COORD REGAZ PRODResponsable applicatif : TALMOUDI, Abdelkader - G603655Contact mainteneur : MKADDEM, Oussama - G701089Besoin certificat HTTPS : NonBesoin d'un alias DNS (à créer ou modifier) : NonNetmask : 255.255.255.248VLAN : 3006Gateway : 10.81.128.49IP serveur : 10.81.128.54Action : CréationHébergement du serveur : Central (BLB)Nouveau VLAN : NonService/CI associé au serveur : COORDINATEUR_1G_REGAZ_GEGBesoin d'envoyer des mails via nos passerelles SMTP : OuiModèle : VMware Virtual PlatformDescription serveur : Coordinateur PROD 1G REGAZ | N25: G_IT_SC_ASKIT | O25: G_IT_SC_ASKIT | P25: G_IT_SC_ASKIT | Q25: ABBAR, Ahcene | R25: G_IT_SC_ASKIT | S25: Terminé | T25: 0 | U25: Clôturé | V25: WF_CMDB_SERV_ASKIT
A26: S260602_019 | B26: HAMMOUDA, Imen | C26: G361243 | D26: BEN ABDALLAH, Mehdi | E26: supports | F26: Tunisie/Megrine | G26: 46175.303 | H26: 46175.449 | I26: ASKit MAJ CMDB | J26: 3 | K26: Nom du serveur : BLB28065Type de serveur : Virtuel (VM)Système d'exploitation du serveur : Debian 13Espace disque du serveur (en Go) : 20 GO sous /home + 20 GO sous /varRAM Serveur (en Go) : 4Nombre de processeur et modèle pour serveur : 4Expression du besoin : Bonjour, Pouvez-vous créer cette machine dans le VLAN: DMZ_Privee VLAN 922. la machine va remplacer RMM08184, elle doit être dans le même VLAN. Cordialement, Imen Besoin en supervision : OuiBesoin en sauvegarde : OuiDescription de ce qui doit être sauvegardé : sauvegarde machineNature du serveur : PRODContact technique : HAMMOUDA, Imen - G361243Besoin réseau : Accès uniquement par SagemcomDate de mise en œuvre souhaitée : 15/05/2026Besoin d'une seconde sauvegarde sur un site distinct de Bois-Colombes : NonMatrice de flux : 95119Titre : VM MIGRATION COORD SIBELGA PRODResponsable applicatif : TALMOUDI, Abdelkader - G603655Contact mainteneur : MKADDEM, Oussama - G701089Besoin certificat HTTPS : NonBesoin d'un alias DNS (à créer ou modifier) : NonNetmask : 255.255.255.248VLAN : 3252Gateway : 10.81.130.145IP serveur : 10.81.130.147Action : CréationHébergement du serveur : Central (BLB)Nouveau VLAN : NonService/CI associé au serveur : COORDINATEUR_1G_SIBELGABesoin d'envoyer des mails via nos passerelles SMTP : OuiModèle : VMware Virtual PlatformDescription serveur : Coordinateur PROD 1G SIBELGACréation du serveur : OuiCréation serveur en CI : OuiLien CI service-serveur : OuiNom du serveur : BLB28065Type de serveur : Virtuel (VM)Système d'exploitation du serveur : Debian 13Espace disque du serveur (en Go) : 20 GO sous /home + 20 GO sous /varRAM Serveur (en Go) : 4Nombre de processeur et modèle pour serveur : 4Expression du besoin : Bonjour, Pouvez-vous créer cette machine dans le VLAN: DMZ_Privee VLAN 922. la machine va remplacer RMM08184, elle doit être dans le même VLAN. Cordialement, Imen Besoin en supervision : OuiBesoin en sauvegarde : OuiDescription de ce qui doit être sauvegardé : sauvegarde machineNature du serveur : PRODContact technique : HAMMOUDA, Imen - G361243Besoin réseau : Accès uniquement par SagemcomDate de mise en œuvre souhaitée : 15/05/2026Besoin d'une seconde sauvegarde sur un site distinct de Bois-Colombes : NonMatrice de flux : 95119Titre : VM MIGRATION COORD SIBELGA PRODResponsable applicatif : TALMOUDI, Abdelkader - G603655Contact mainteneur : MKADDEM, Oussama - G701089Besoin certificat HTTPS : NonBesoin d'un alias DNS (à créer ou modifier) : NonNetmask : 255.255.255.248VLAN : 3252Gateway : 10.81.130.145IP serveur : 10.81.130.147Action : CréationHébergement du serveur : Central (BLB)Nouveau VLAN : NonService/CI associé au serveur : COORDINATEUR_1G_SIBELGABesoin d'envoyer des mails via nos passerelles SMTP : OuiModèle : VMware Virtual PlatformDescription serveur : Coordinateur PROD 1G SIBELGA | N26: G_IT_SC_ASKIT | O26: G_IT_SC_ASKIT | P26: G_IT_SC_ASKIT | Q26: ABBAR, Ahcene | R26: G_IT_SC_ASKIT | S26: Terminé | T26: 0 | U26: Clôturé | V26: WF_CMDB_SERV_ASKIT
A27: S260602_020 | B27: HAMMOUDA, Imen | C27: G361243 | D27: BEN ABDALLAH, Mehdi | E27: supports | F27: Tunisie/Megrine | G27: 46175.304 | H27: 46175.449 | I27: ASKit MAJ CMDB | J27: 3 | K27: Nom du serveur : BLB28066Type de serveur : Virtuel (VM)Système d'exploitation du serveur : Debian 13Espace disque du serveur (en Go) : 70 GO sous /home + 200 GO sous /varRAM Serveur (en Go) : 8 GONombre de processeur et modèle pour serveur : 4Expression du besoin : Bonjour, Pouvez-vous créer cette machine dans le VLAN: DMZ_Privee VLAN 922. la machine va remplacer RMM08182, elle doit être dans le même VLAN. Cordialement, Imen. Besoin en supervision : OuiBesoin en sauvegarde : OuiDescription de ce qui doit être sauvegardé : sauvegarde machineNature du serveur : PRODContact technique : HAMMOUDA, Imen - G361243Besoin réseau : Accès uniquement par SagemcomDate de mise en œuvre souhaitée : 15/05/2026Besoin d'une seconde sauvegarde sur un site distinct de Bois-Colombes : NonMatrice de flux : 95117Titre : VM MIGRATION COORD ENEXIS PRODResponsable applicatif : TALMOUDI, Abdelkader - G603655Contact mainteneur : MKADDEM, Oussama - G701089Besoin certificat HTTPS : NonBesoin d'un alias DNS (à créer ou modifier) : NonNetmask : 255.255.255.248VLAN : 3253Gateway : 10.81.130.153IP serveur : 10.81.130.155Action : CréationHébergement du serveur : Central (BLB)Nouveau VLAN : NonService/CI associé au serveur : COORDINATEUR_1G_ENEXISBesoin d'envoyer des mails via nos passerelles SMTP : OuiModèle : VMware Virtual PlatformDescription serveur : Coordinateur PROD 1G ENEXISCréation du serveur : OuiCréation serveur en CI : OuiLien CI service-serveur : OuiNom du serveur : BLB28066Type de serveur : Virtuel (VM)Système d'exploitation du serveur : Debian 13Espace disque du serveur (en Go) : 70 GO sous /home + 200 GO sous /varRAM Serveur (en Go) : 8 GONombre de processeur et modèle pour serveur : 4Expression du besoin : Bonjour, Pouvez-vous créer cette machine dans le VLAN: DMZ_Privee VLAN 922. la machine va remplacer RMM08182, elle doit être dans le même VLAN. Cordialement, Imen. Besoin en supervision : OuiBesoin en sauvegarde : OuiDescription de ce qui doit être sauvegardé : sauvegarde machineNature du serveur : PRODContact technique : HAMMOUDA, Imen - G361243Besoin réseau : Accès uniquement par SagemcomDate de mise en œuvre souhaitée : 15/05/2026Besoin d'une seconde sauvegarde sur un site distinct de Bois-Colombes : NonMatrice de flux : 95117Titre : VM MIGRATION COORD ENEXIS PRODResponsable applicatif : TALMOUDI, Abdelkader - G603655Contact mainteneur : MKADDEM, Oussama - G701089Besoin certificat HTTPS : NonBesoin d'un alias DNS (à créer ou modifier) : NonNetmask : 255.255.255.248VLAN : 3253Gateway : 10.81.130.153IP serveur : 10.81.130.155Action : CréationHébergement du serveur : Central (BLB)Nouveau VLAN : NonService/CI associé au serveur : COORDINATEUR_1G_ENEXISBesoin d'envoyer des mails via nos passerelles SMTP : OuiModèle : VMware Virtual PlatformDescription serveur : Coordinateur PROD 1G ENEXIS | N27: G_IT_SC_ASKIT | O27: G_IT_SC_ASKIT | P27: G_IT_SC_ASKIT | Q27: ABBAR, Ahcene | R27: G_IT_SC_ASKIT | S27: Terminé | T27: 0 | U27: Clôturé | V27: WF_CMDB_SERV_ASKIT
A28: S260602_021 | B28: HAMMOUDA, Imen | C28: G361243 | D28: BEN ABDALLAH, Mehdi | E28: supports | F28: Tunisie/Megrine | G28: 46175.305 | H28: 46175.449 | I28: ASKit MAJ CMDB | J28: 3 | K28: Nom du serveur : BLB29032Type de serveur : Virtuel (VM)Système d'exploitation du serveur : Debian 13Espace disque du serveur (en Go) : 10 GO sous /home & 10 GO sous /varRAM Serveur (en Go) : 4 GONombre de processeur et modèle pour serveur : 'Expression du besoin : Bonjour, Pouvez-vous créer cette machine dans le VLAN: DMZ_Privee VLAN 922. la machine va remplacer RMM08194, elle doit être dans le même VLAN. Cordialement, Imen.Besoin en supervision : OuiBesoin en sauvegarde : OuiDescription de ce qui doit être sauvegardé : sauvegarde machineNature du serveur : VALContact technique : HAMMOUDA, Imen - G361243Besoin réseau : Accès uniquement par SagemcomDate de mise en œuvre souhaitée : 22/05/2026Matrice de flux : 95114Titre : VM MIGRATION COORD TNB VALResponsable applicatif : TALMOUDI, Abdelkader - G603655Contact mainteneur : MKADDEM, Oussama - G701089Besoin certificat HTTPS : NonBesoin d'un alias DNS (à créer ou modifier) : NonNetmask : 255.255.255.248VLAN : 3254Gateway : 10.81.130.161IP serveur : 10.81.130.162Action : CréationHébergement du serveur : Central (BLB)Nouveau VLAN : OuiService/CI associé au serveur : COORDINATEUR_1G_TNBBesoin d'envoyer des mails via nos passerelles SMTP : OuiModèle : VMware Virtual PlatformDescription serveur : Coordinateur VAL 1G VALCréation du serveur : OuiCréation serveur en CI : OuiLien CI service-serveur : OuiNom du serveur : BLB29032Type de serveur : Virtuel (VM)Système d'exploitation du serveur : Debian 13Espace disque du serveur (en Go) : 10 GO sous /home & 10 GO sous /varRAM Serveur (en Go) : 4 GONombre de processeur et modèle pour serveur : 'Expression du besoin : Bonjour, Pouvez-vous créer cette machine dans le VLAN: DMZ_Privee VLAN 922. la machine va remplacer RMM08194, elle doit être dans le même VLAN. Cordialement, Imen.Besoin en supervision : OuiBesoin en sauvegarde : OuiDescription de ce qui doit être sauvegardé : sauvegarde machineNature du serveur : VALContact technique : HAMMOUDA, Imen - G361243Besoin réseau : Accès uniquement par SagemcomDate de mise en œuvre souhaitée : 22/05/2026Matrice de flux : 95114Titre : VM MIGRATION COORD TNB VALResponsable applicatif : TALMOUDI, Abdelkader - G603655Contact mainteneur : MKADDEM, Oussama - G701089Besoin certificat HTTPS : NonBesoin d'un alias DNS (à créer ou modifier) : NonNetmask : 255.255.255.248VLAN : 3254Gateway : 10.81.130.161IP serveur : 10.81.130.162Action : CréationHébergement du serveur : Central (BLB)Nouveau VLAN : OuiService/CI associé au serveur : COORDINATEUR_1G_TNBBesoin d'envoyer des mails via nos passerelles SMTP : OuiModèle : VMware Virtual PlatformDescription serveur : Coordinateur VAL 1G VAL | N28: G_IT_SC_ASKIT | O28: G_IT_SC_ASKIT | P28: G_IT_SC_ASKIT | Q28: ABBAR, Ahcene | R28: G_IT_SC_ASKIT | S28: Terminé | T28: 0 | U28: Clôturé | V28: WF_CMDB_SERV_ASKIT
A29: S260602_022 | B29: BEN MANSOUR, Hakim | C29: G545685 | D29: SAMANDI, Sami | E29: AVS | F29: Tunisie/Megrine | G29: 46175.306 | H29: 46175.448 | I29: ASKit MAJ CMDB | J29: 3 | K29: Expression du besoin : Mise hors service temporaire du serveur (arrêt technique), avec retrait temporaire de l’Active Directory, dans un objectif d’optimisation des ressources et de réutilisation ultérieure planifiée.Titre : Décommissionnement temporaire du serveurNom du serveur : sstflux14.ads.local : 10.206.213.14Action : DécommissionnementDate d'arrêt : 09/03/2026Besoin d'une sauvegarde : NonServeur non trouvé dans la liste ci-dessus : 1 | N29: G_IT_SC_ASKIT | O29: G_IT_SC_ASKIT | P29: G_IT_SC_ASKIT | Q29: ABBAR, Ahcene | R29: G_IT_SC_ASKIT | S29: Terminé | T29: 0 | U29: Clôturé | V29: WF_CMDB_SERV_ASKIT
A30: S260602_023 | B30: BEN MANSOUR, Hakim | C30: G545685 | D30: SAMANDI, Sami | E30: AVS | F30: Tunisie/Megrine | G30: 46175.307 | H30: 46175.447 | I30: ASKit MAJ CMDB | J30: 3 | K30: Expression du besoin : Mise hors service temporaire du serveur (arrêt technique), avec retrait temporaire de l’Active Directory, dans un objectif d’optimisation des ressources et de réutilisation ultérieure planifiée.Titre : Décommissionnement temporaire du serveurNom du serveur : sstflux33.ads.local : 10.206.213.33Action : DécommissionnementDate d'arrêt : 09/03/2026Besoin d'une sauvegarde : NonServeur non trouvé dans la liste ci-dessus : 1 | N30: G_IT_SC_ASKIT | O30: G_IT_SC_ASKIT | P30: G_IT_SC_ASKIT | Q30: ABBAR, Ahcene | R30: G_IT_SC_ASKIT | S30: Terminé | T30: 0 | U30: Clôturé | V30: WF_CMDB_SERV_ASKIT
A31: S260602_024 | B31: BEN MANSOUR, Hakim | C31: G545685 | D31: SAMANDI, Sami | E31: AVS | F31: Tunisie/Megrine | G31: 46175.308 | H31: 46175.447 | I31: ASKit MAJ CMDB | J31: 3 | K31: Expression du besoin : Mise hors service temporaire du serveur (arrêt technique), avec retrait temporaire de l’Active Directory, dans un objectif d’optimisation des ressources et de réutilisation ultérieure planifiée.Titre : Décommissionnement temporaire du serveurNom du serveur : srv-pbt02.ads.local 10.206.213.35Action : DécommissionnementDate d'arrêt : 09/03/2026Besoin d'une sauvegarde : NonServeur non trouvé dans la liste ci-dessus : 1 | N31: G_IT_SC_ASKIT | O31: G_IT_SC_ASKIT | P31: G_IT_SC_ASKIT | Q31: ABBAR, Ahcene | R31: G_IT_SC_ASKIT | S31: Terminé | T31: 0 | U31: Clôturé | V31: WF_CMDB_SERV_ASKIT
... A33: S260602_026 | B33: BEN MANSOUR, Hakim | C33: G545685 | D33: SAMANDI, Sami | E33: AVS | F33: Tunisie/Megrine | G33: 46175.31 | H33: 46175.447 | I33: ASKit MAJ CMDB | J33: 3 | K33: Expression du besoin : Mise hors service temporaire du serveur (arrêt technique), avec retrait temporaire de l’Active Directory, dans un objectif d’optimisation des ressources et de réutilisation ultérieure planifiée.Titre : Décommissionnement temporaire du serveurNom du serveur : sst-flux21.ads.local : 10.206.213.21Action : DécommissionnementDate d'arrêt : 09/03/2026Besoin d'une sauvegarde : NonServeur non trouvé dans la liste ci-dessus : 1 | N33: G_IT_SC_ASKIT | O33: G_IT_SC_ASKIT | P33: G_IT_SC_ASKIT | Q33: ABBAR, Ahcene | R33: G_IT_SC_ASKIT | S33: Terminé | T33: 0 | U33: Clôturé | V33: WF_CMDB_SERV_ASKIT
A34: S260602_096 | B34: KCHAYEH, Mourad | C34: G701445 | D34: SAMANDI, Sami | E34: AVS | F34: Tunisie/Megrine | G34: 46175.421 | H34: 46184.4 | I34: Souris | J34: 3 | K34: 1 x Souris : 0 EUR1 x Souris filaire : 9.43 EURCentre de coût : S250201 | L34: Accepter Pour accepter la demande, cliquez simplement sur le bouton d'envoi de ce mail. Ne modifiez pas le texte ci dessous @OPERATION@='SOLVE' @RFC_NUMBER@='S260602_096' @CHOICE@='1' bonjoursouris est disponiblecordialement | N34: G_IT_DESKTOP_SST | P34: G_IT_DESKTOP_SST | Q34: BOUFAHJA, Kamel | R34: G_IT_DESKTOP_SST | S34: Terminé | T34: 3.0423611 | U34: Clôturé | V34: WF_REQ_GENERIC_V6.1
A35: S260602_120 | B35: BEN ABBES, Mohamed Ali | C35: G702003 | D35: MAROUFI, Walid | E35: E&T | F35: Tunisie/Sousse | G35: 46175.444 | H35: 46182.418 | I35: Gestion des flux | J35: 3 | K35: 1 x Gestion des flux : 0 EURTitre : ingenieur devAction demandée : CréationProjet/Application : water meterService/CI associé au serveur : BLB_INFRA_SERVERSSite destination : BLB (France/Bois Colombes)Adresses IP sources : g702003Adresses IP destination : https://nexus-produits.rmm.scom/Port destination : 443Date de début de la mission : 02/06/2026 | N35: G_IT_NETWORK_BLB | P35: G_IT_SECURITY | Q35: OGRYZEK, Damien | R35: G_IT_NETWORK_BLB | S35: Terminé | T35: 2.1618056 | U35: Clôturé | V35: WF_REQ_GENERIC_V6.1
A36: S260602_131 | B36: STAMBOULI, Mohamed Fawzi | C36: G801097 | D36: MAROUFI, Walid | E36: E&T | F36: Tunisie/Sousse | G36: 46175.463 | H36: 46181.664 | I36: PC Desktop | J36: 3 | K36: 1 x PC Desktop : 0 USD1 x Desktop Dev. : 588 USD1 x Aucun écran : USDType : Intégré au domaine SagemcomConfiguration : Configuration développementOS : WindowsClavier : AZERTYCentre de coût : S250300Email de validation de son DIR pôle à joindre : RE Demande dextension de RAM.msg | L36: Bonjour ,Demande traitéCordialement. | N36: G_IT_DESKTOP_SST | P36: G_IT_DESKTOP_KRM | Q36: MFARREJ, Yosri | R36: G_IT_DESKTOP_SST | S36: Terminé | T36: 1.2625 | U36: Clôturé | V36: WF_REQ_GENERIC_V6.1
A37: S260602_133 | B37: HERMI, Yassine | C37: G801098 | D37: MAROUFI, Walid | E37: E&T | F37: Tunisie/Sousse | G37: 46175.465 | H37: 46181.664 | I37: PC Desktop | J37: 3 | K37: 1 x PC Desktop : 0 USD1 x Desktop Dev. : 588 USD1 x Aucun écran : USDType : Intégré au domaine SagemcomConfiguration : Configuration développementOS : WindowsClavier : AZERTYCentre de coût : S250300Email de validation de son DIR pôle à joindre : RE Demande dextension de RAM.msg | L37: Bonjour ,Demande traitéCordialement. | N37: G_IT_DESKTOP_SST | P37: G_IT_DESKTOP_KRM | Q37: MFARREJ, Yosri | R37: G_IT_DESKTOP_SST | S37: Terminé | T37: 1.2597222 | U37: Clôturé | V37: WF_REQ_GENERIC_V6.1
A38: S260602_193 | B38: THABTI, Thamer | C38: G701076 | D38: MAROUFI, Walid | E38: E&T | F38: Tunisie/Kram | G38: 46175.613 | H38: 46204.518 | I38: Demande d'accès bureautique | J38: 3 | K38: 1 x Demande d'accès bureautique : 0 EURAction : AjoutNom du PC : P1312188Type d'accès : Accès imprimante (Réseau)Justification de la demande : Bonjour,je vous prie de bien vouloir m'accorder le droit d'accès à l'imprimante située à la mezzanine du site de Kram. Merci d'avance.Cordialement,Thamer. | L38: ​Bonjour ,Demande traitée Cdt, | N38: G_IT_DESKTOP_KRM | P38: G_IT_DESKTOP_KRM | Q38: DRIDI, Rimeh | R38: G_IT_DESKTOP_KRM | S38: Terminé | T38: 9.0923611 | U38: Clôturé | V38: WF_REQ_GENERIC_V6.1
A39: S260602_217 | B39: THELJAOUI, Mohamed | C39: G361247 | D39: BEN ABDALLAH, Mehdi | E39: supports | F39: Tunisie/Megrine | G39: 46175.656 | H39: 46176.54 | I39: Gestion des flux | J39: 2 | K39: 1 x Gestion des flux : 0 EURTitre : Flux vers port 5432Action demandée : CréationProjet/Application : activiti PRODSite destination : BLB (France/Bois Colombes)Adresses IP sources : SST-Dsi-AppliMetierAdresses IP destination : 10.81.129.170Port destination : 5432Date de début de la mission : 02/06/2026 | L39: Flux déjà ouvert. | N39: G_IT_NETWORK_BLB | P39: G_IT_SECURITY | Q39: AHMANE, Hassan | R39: G_IT_NETWORK_BLB | S39: Terminé | T39: 0.32083333 | U39: Clôturé | V39: WF_REQ_GENERIC_V6.1
A40: S260602_218 | B40: SEDDIKI, Marwa | C40: G573268 | D40: MASMOUDI, Oussema | E40: BBS | F40: Tunisie/Megrine | G40: 46175.658 | H40: 46176.422 | I40: Accès PMAD | J40: 2 | K40: 1 x Accès PMAD : 0 EURType de PMAD : Cygnus : Bastion administration vers les équipements hors Sagemcom (réseaux de test, cloud, partenaire ...) | L40: Accès cygnus créé vers la serveur ovh99003 | N40: G_IT_INFRA_BLB | P40: G_IT_INFRA_BLB | Q40: MELENOTTE, Philippe | R40: G_IT_INFRA_BLB | S40: Terminé | T40: 0.20138889 | U40: Clôturé | V40: WF_REQ_GENERIC_V6.1
A41: S260602_241 | B41: KHELIL, Yasmine | C41: G573492 | D41: MAROUFI, Walid | E41: E&T | F41: Tunisie/Kram | G41: 46175.69 | I41: Mémoire | J41: 3 | K41: 1 x Mémoire : 60 EURAjout de : 16 GoType d'UC : PortableN° étiquette du PC (ou modèle) : P1312461Centre de coût : S250300 | L41: @équipe IT : veuillez réaliser les diagnostics nécessaires à contacter MCHITA Karim en cas de besoin matériels | N41: G_IT_DESKTOP_KRM | O41: G_IT_DESKTOP_KRM | R41: G_IT_DESKTOP_KRM | S41: En attente | T41: 0 | U41: Suspendu | V41: WF_REQ_GENERIC_V6.1
...

Sheet tickets fermés
A1: N° ticket | B1: Bénéficiaire | C1: Bénéficiaire ID | D1: Enregistré le | E1: Date de résolution | F1: Sujet | G1: Priorité | H1: E_REPONSES | I1: Description | J1: Bénéficiaire : Niveau de VIP | K1: Bénéficiaire : Localisation | L1: GROUP_$lng | M1: Groupe courant | N1: Résolu par (groupe) | O1: Résolu par (intervenant) | P1: GROUP_$lng | Q1: Meta Statut | R1: Délai de résolution (min) | S1: Statut ticket | T1: Workflow
A2: S260119_407 | B2: TALEB ALI, Mariem | C2: G701304 | D2: 46041.694 | E2: 46178.504 | F2: Installation réseau ou téléphone fixe | G2: 3 | H2: 1 x Installation réseau ou téléphone fixe : 0 EURDemande Réseau ou Téléphonie : RéseauBesoin extention cablage reseau : ATRdésignation : Bonjour, Besoin de ligne réseau Sagem Plateau : C0 Emplacement: G2 Port: D0-243 merci | I2: Bonjour Merci de tester port 243 cdt Bonjour,la ligne 243 n'est pas pratique, le support de port est cassé.Merci de le voir.Mariem Bonjour,Problème résolu.Cdt, | K2: Tunisie/Megrine | L2: G_IT_NETWORK_KRM | N2: G_IT_NETWORK_SST | O2: SMAALI, Slim | P2: G_IT_NETWORK_KRM | Q2: Terminé | R2: 27.488194 | S2: Clôturé | T2: WF_REQ_GENERIC_V6.1
A3: S260122_257 | B3: TRABELSI, Khalil | C3: G701090 | D3: 46044.617 | E3: 46174.554 | F3: Serveur | G3: 3 | H3: 1 x Serveur : 0 USD Titre : RMM08471 Décommissionnement Action : Décommissionnement Nom du serveur (recherche par nom ou IP) : rmm08471 Serveur non trouvé dans la liste ci-dessus : 0 Date d'arrêt : 15/02/2026 Besoin d'une sauvegarde : Oui | I3: Sortie Inventaire / PMAD Suppression de l'ip effectuée sur IPAM et firewalls --> RMM08471,10.81.130.43 Suppression de l'ip effectuée sur IPAM et firewalls --> RMM08471,10.81.130.43 | K3: Tunisie/Megrine | L3: G_IT_INFRA_BLB | M3: G_IT_SC_ASKIT | N3: G_IT_INFRA_BLB | O3: GAUTREAU, Fabien | P3: G_IT_INFRA_BLB | Q3: Terminé | R3: 26.368056 | S3: Clôturé | T3: WF_REQ_IT_SERVER_FOR_APPS_V13+ETL
A4: S260122_310 | B4: TRABELSI, Khalil | C4: G701090 | D4: 46044.67 | E4: 46174.525 | F4: Serveur | G4: 3 | H4: 1 x Serveur : 0 USD Titre : RMM08469 Décommissionnement Action : Décommissionnement Nom du serveur (recherche par nom ou IP) : rmm08469 Serveur non trouvé dans la liste ci-dessus : 0 Date d'arrêt : 28/02/2026 Besoin d'une sauvegarde : Oui | I4: Sortie inventaire Suppression de l'ip effectuée sur IPAM et firewalls Suppression de l'ip effectuée sur IPAM et firewalls --> RMM08469,10.81.130.37 | K4: Tunisie/Megrine | L4: G_IT_INFRA_BLB | M4: G_IT_SC_ASKIT | N4: G_IT_INFRA_BLB | O4: GAUTREAU, Fabien | P4: G_IT_INFRA_BLB | Q4: Terminé | R4: 10.622222 | S4: Clôturé | T4: WF_REQ_IT_SERVER_FOR_APPS_V13+ETL
A5: S260122_330 | B5: TRABELSI, Khalil | C5: G701090 | D5: 46044.679 | E5: 46174.525 | F5: Serveur | G5: 3 | H5: 1 x Serveur : 0 USD Titre : RMM08461 Decommissionnement Action : Décommissionnement Nom du serveur (recherche par nom ou IP) : rmm08461 Serveur non trouvé dans la liste ci-dessus : 0 Date d'arrêt : 28/02/2026 Besoin d'une sauvegarde : Oui | I5: Service migré sur blb28012.ads.local Sortie Inventaire / PMAD Suppression de l'ip effectuée sur IPAM et firewalls Reutilisation de l'IPGarde le nom pour compatibilité applicative | K5: Tunisie/Megrine | L5: G_IT_INFRA_BLB | M5: G_IT_SC_ASKIT | N5: G_IT_INFRA_BLB | O5: GAUTREAU, Fabien | P5: G_IT_INFRA_BLB | Q5: Terminé | R5: 11.638889 | S5: Clôturé | T5: WF_REQ_IT_SERVER_FOR_APPS_V13+ETL
A6: S260122_335 | B6: TRABELSI, Khalil | C6: G701090 | D6: 46044.682 | E6: 46174.521 | F6: Serveur | G6: 3 | H6: 1 x Serveur : 0 USD Titre : RMM08467 Decommissionnement Action : Décommissionnement Nom du serveur (recherche par nom ou IP) : rmm08467 Serveur non trouvé dans la liste ci-dessus : 0 Date d'arrêt : 28/02/2026 Besoin d'une sauvegarde : Oui | I6: Sortie Inventire Sortie inventaire Suppression de l'ip effectuée sur IPAM et firewalls sur l'ip du serveur RMM08467,10.81.130.39 Suppression de l'ip effectuée sur IPAM et firewalls sur l'ip du serveur RMM08467,10.81.130.39 | K6: Tunisie/Megrine | L6: G_IT_INFRA_BLB | M6: G_IT_SC_ASKIT | N6: G_IT_INFRA_BLB | O6: GAUTREAU, Fabien | P6: G_IT_INFRA_BLB | Q6: Terminé | R6: 11.975 | S6: Clôturé | T6: WF_REQ_IT_SERVER_FOR_APPS_V13+ETL
A7: S260213_180 | B7: HAYOUNI, Mahdi | C7: G800063 | D7: 46066.602 | E7: 46196.425 | F7: PC accessoires | G7: 3 | H7: 1 x PC accessoires : 0 EUR1 x Filtre de confidentialité : 27 USD1 x Câble de sécurité : 13.04 USD1 x Sac à dos Laptop : 16.7 EURN° étiquette du PC (ou modèle) : 1313572Autres accessoires : NonCentre de coût : S250300 | I7: demande annulée | K7: Tunisie/Kram | L7: G_IT_DESKTOP_KRM | N7: G_IT_DESKTOP_KRM | O7: GARRAWI, Sana | P7: G_IT_DESKTOP_KRM | Q7: Terminé | R7: 3.2493056 | S7: Clôturé | T7: WF_REQ_GENERIC_V6.1
